Workbook
Name UnitNames: Units!$B$2:$B$15

Sheet Read Me
B2: Roll the Reckoning — Units & Dice Design
B3: Working roster + rarity math for the dice-roll -> unit-draft loop, plus the village-slot and dice-deck ideas it feeds into.
B5: Tab | C5: What it's for
B6: Units | C6: The master roster. One row per unit type. Edit the blue cells (Draft Pool, Base Damage, Base HP, Notes). Everything else is looked up elsewhere.
B7: Rarity Variants | C7: Every unit x quality-tier (Common -> Legendary) combo, with stats scaled by the multipliers on 'Rarity Scale'. This is what a specific roll actually produces in-game.
B8: Roll Tiers | C8: How a TYPE roll (2d6 sum) maps to a Draft Pool, mirroring Scripts/main.gd's SUM_TO_RANGE and the in-game Roll Ledger. Live counts pull from Units automatically.
B9: Village Loadouts | C9: 5-slots-per-village planning sheet. One row per village; pick which units (by name) fill its 5 slots. Slot cells are dropdowns built from Units.
B10: Dice & Deck Notes | C10: Open design questions for the Slay-the-Spire-style dice bag/hand idea. Not mechanically wired yet - this is a scratchpad, not a spec.
B12: Legend
B13: Blue text | C13: A value you're meant to edit (stats, names, notes).
B14: Black text | C14: A formula - don't overtype it, it recalculates from the blue cells.
B15: Yellow fill | C15: A design note / open question, not game data.
B16: Green fill | C16: Example row(s) showing the expected format - replace or add more below them.
B18: All base stats and rarity multipliers below are starter placeholders for balance passes, in the same spirit as main.gd's own CLASH_SIEGE_DAMAGE comment ("treat these numbers as placeholders to rebalance once real rules are nailed down"). Nothing here is wired into the game yet - Scripts/main.gd currently drafts generic placeholder avatar icons, not these named units. Wiring real sprites in as unit icons is a follow-up task once the roster below is locked.

Sheet Units
A1: Unit ID | B1: Unit Name | C1: Theme | D1: Draft Pool | E1: Sum Range | F1: Base Damage | G1: Base HP | H1: Asset Source | I1: Sprite Status | J1: Notes / Abilities (future)
A2: U01 | B2: Minotaur | C2: Beast - Boss | D2: Boss | E2: =IF($D2="Boss",'Roll Tiers'!$A$4,IF($D2="Common",'Roll Tiers'!$A$6,IF($D2="Rare",'Roll Tiers'!$A$5&", "&'Roll Tiers'!$A$7,"?"))) | F2: 8 | G2: 40 | H2: Tiny Swords (Enemy Pack)/Enemy Pack/Minotaur | I2: Full sprite sheet (Idle/Attack/Guard/Walk) | J2: Single boss slot - only the 2-2 roll drafts it. Guard frame suggests a block/counter ability later.
A3: U02 | B3: Troll | C3: Beast - Rare | D3: Rare | E3: =IF($D3="Boss",'Roll Tiers'!$A$4,IF($D3="Common",'Roll Tiers'!$A$6,IF($D3="Rare",'Roll Tiers'!$A$5&", "&'Roll Tiers'!$A$7,"?"))) | F3: 5 | G3: 20 | H3: Tiny Swords (Enemy Pack)/Enemy Pack/Troll | I3: Full sprite sheet (Attack/Windup/Recovery/Dead/Walk) | J3: Windup/Recovery frames fit a slow-but-hard-hitting attack.
A4: U03 | B4: Panda | C4: Beast - Rare | D4: Rare | E4: =IF($D4="Boss",'Roll Tiers'!$A$4,IF($D4="Common",'Roll Tiers'!$A$6,IF($D4="Rare",'Roll Tiers'!$A$5&", "&'Roll Tiers'!$A$7,"?"))) | F4: 4 | G4: 18 | H4: Tiny Swords (Enemy Pack)/Enemy Pack/Panda | I4: Full sprite sheet (Attack/Guard/Run) | J4: Guard frame - candidate for a damage-reduction ability.
A5: U04 | B5: Shaman | C5: Caster - Rare | D5: Rare | E5: =IF($D5="Boss",'Roll Tiers'!$A$4,IF($D5="Common",'Roll Tiers'!$A$6,IF($D5="Rare",'Roll Tiers'!$A$5&", "&'Roll Tiers'!$A$7,"?"))) | F5: 4 | G5: 12 | H5: Tiny Swords (Enemy Pack)/Enemy Pack/Shaman | I5: Full sprite sheet (Attack/Projectile/Explosion/Run) | J5: Ranged/AoE - Explosion frame suggests a splash-damage ability.
A6: U05 | B6: Lancer | C6: Humanoid - Rare | D6: Rare | E6: =IF($D6="Boss",'Roll Tiers'!$A$4,IF($D6="Common",'Roll Tiers'!$A$6,IF($D6="Rare",'Roll Tiers'!$A$5&", "&'Roll Tiers'!$A$7,"?"))) | F6: 5 | G6: 14 | H6: Tiny Swords (Enemy Pack)/Enemy Pack/Lancer | I6: Full sprite sheet (Attack/Idle/Run) | J6: Armored spear unit - straightforward melee rare.
A7: U06 | B7: Spider | C7: Beast - Rare | D7: Rare | E7: =IF($D7="Boss",'Roll Tiers'!$A$4,IF($D7="Common",'Roll Tiers'!$A$6,IF($D7="Rare",'Roll Tiers'!$A$5&", "&'Roll Tiers'!$A$7,"?"))) | F7: 4 | G7: 10 | H7: Tiny Swords (Enemy Pack)/Enemy Pack/Spider | I7: Full sprite sheet (Attack/Run) | J7: Fast/fragile - candidate for a web/slow debuff later.
A8: U07 | B8: Skull | C8: Undead - Common | D8: Common | E8: =IF($D8="Boss",'Roll Tiers'!$A$4,IF($D8="Common",'Roll Tiers'!$A$6,IF($D8="Rare",'Roll Tiers'!$A$5&", "&'Roll Tiers'!$A$7,"?"))) | F8: 2 | G8: 6 | H8: Tiny Swords (Enemy Pack)/Enemy Pack/Skull | I8: Full sprite sheet (Attack/Guard/Run) | J8: Cheap undead fodder - fields well in numbers per the doc's "weak alone, field 6" idea.
A9: U08 | B9: Gnoll | C9: Goblinoid - Common | D9: Common | E9: =IF($D9="Boss",'Roll Tiers'!$A$4,IF($D9="Common",'Roll Tiers'!$A$6,IF($D9="Rare",'Roll Tiers'!$A$5&", "&'Roll Tiers'!$A$7,"?"))) | F9: 3 | G9: 8 | H9: Tiny Swords (Enemy Pack)/Enemy Pack/Gnoll | I9: Full sprite sheet (Bone/Hit/Idle/Throw/Walk) | J9: Throw frame - ranged bone-throw common.
A10: U09 | B10: Gnome | C10: Goblinoid - Common | D10: Common | E10: =IF($D10="Boss",'Roll Tiers'!$A$4,IF($D10="Common",'Roll Tiers'!$A$6,IF($D10="Rare",'Roll Tiers'!$A$5&", "&'Roll Tiers'!$A$7,"?"))) | F10: 1 | G10: 5 | H10: Tiny Swords (Enemy Pack)/Enemy Pack/Gnome | I10: Full sprite sheet (Attack/Idle/Run) | J10: Weakest common - highest-count filler unit.
A11: U10 | B11: Snake | C11: Beast - Common | D11: Common | E11: =IF($D11="Boss",'Roll Tiers'!$A$4,IF($D11="Common",'Roll Tiers'!$A$6,IF($D11="Rare",'Roll Tiers'!$A$5&", "&'Roll Tiers'!$A$7,"?"))) | F11: 3 | G11: 5 | H11: Tiny Swords (Enemy Pack)/Enemy Pack/Snake | I11: Full sprite sheet (Attack/Run) | J11: Glass - candidate for a poison/DoT tick later.
A12: U11 | B12: Lizard | C12: Beast - Common | D12: Common | E12: =IF($D12="Boss",'Roll Tiers'!$A$4,IF($D12="Common",'Roll Tiers'!$A$6,IF($D12="Rare",'Roll Tiers'!$A$5&", "&'Roll Tiers'!$A$7,"?"))) | F12: 2 | G12: 7 | H12: Tiny Swords (Enemy Pack)/Enemy Pack/Lizard | I12: Full sprite sheet (Attack/Hit/Run) | J12: Middle-of-the-road common.
A13: U12 | B13: Thief | C13: Humanoid - Common | D13: Common | E13: =IF($D13="Boss",'Roll Tiers'!$A$4,IF($D13="Common",'Roll Tiers'!$A$6,IF($D13="Rare",'Roll Tiers'!$A$5&", "&'Roll Tiers'!$A$7,"?"))) | F13: 2 | G13: 6 | H13: Tiny Swords (Enemy Pack)/Enemy Pack/Thief | I13: Full sprite sheet (Attack/Idle/Run) | J13: Fits the pillage/gold fantasy - candidate for a bonus-gold-on-kill ability.
... A15: U14 | B15: Harpoon Fish | C15: Aquatic - Common | D15: Common | E15: =IF($D15="Boss",'Roll Tiers'!$A$4,IF($D15="Common",'Roll Tiers'!$A$6,IF($D15="Rare",'Roll Tiers'!$A$5&", "&'Roll Tiers'!$A$7,"?"))) | F15: 3 | G15: 6 | H15: Tiny Swords (Enemy Pack)/Enemy Pack/Harpoon Fish | I15: Full sprite sheet (Idle/Run/Throw) | J15: Ranged common - only makes sense for coastal/harbor villages.
B17: Reserve pool - assets exist, not allocated to a Draft Pool yet
B18: Paddle Fish | C18: Aquatic | H18: Tiny Swords (Enemy Pack)/Enemy Pack/Paddle Fish | I18: Full sprite sheet
B19: Bear | C19: Beast | H19: Tiny Swords (Enemy Pack)/Enemy Pack/Bear | I19: Full sprite sheet
B20: Caveborn | C20: Humanoid | H20: Tiny Swords (Enemy Pack)/Enemy Pack/Enemies/Caveborn | I20: Portrait/avatar only - verify sheet before wiring
B21: Goblin Raiders | C21: Goblinoid | H21: Tiny Swords (Enemy Pack)/Enemy Pack/Enemies/Goblin Raiders | I21: Portrait/avatar only - verify sheet before wiring
B22: Pirate Fish | C22: Aquatic | H22: Tiny Swords (Enemy Pack)/Enemy Pack/Enemies/Pirate Fish | I22: Portrait/avatar only - verify sheet before wiring
B23: Root Troll | C23: Beast | H23: Tiny Swords (Enemy Pack)/Enemy Pack/Enemies/Root Troll | I23: Portrait/avatar only - verify sheet before wiring
B24: Bomb Fish | C24: Aquatic | H24: Tiny Swords (Enemy Pack)/Enemy Pack/Enemy Avatars/Bomb Fish.png | I24: Avatar only, no sprite sheet found
B25: Harpoon Shark | C25: Aquatic | H25: Tiny Swords (Enemy Pack)/Enemy Pack/Enemy Avatars/Harpoon Shark.png | I25: Avatar only, no sprite sheet found
B26: Hex Shaman | C26: Caster | H26: Tiny Swords (Enemy Pack)/Enemy Pack/Enemy Avatars/Hex Shaman.png | I26: Avatar only - possibly a Shaman variant portrait
B27: Paddle Shark | C27: Aquatic | H27: Tiny Swords (Enemy Pack)/Enemy Pack/Enemy Avatars/Paddle Shark.png | I27: Avatar only, no sprite sheet found
B28: Spear Goblin | C28: Goblinoid | H28: Tiny Swords (Enemy Pack)/Enemy Pack/Enemy Avatars/Spear Goblin.png | I28: Avatar only, no sprite sheet found
B29: Torch Goblin | C29: Goblinoid | H29: Tiny Swords (Enemy Pack)/Enemy Pack/Enemy Avatars/Torch Goblin.png | I29: Avatar only, no sprite sheet found

Sheet Rarity Variants
A1: Rarity Scale
A2: Matches Scripts/main.gd's Rarity enum / RARITY_NAMES (Die.gd). Your notes call the top tier "Mythic" - currently the code calls it "Legendary". Rename here AND in Die.gd/main.gd together if you want to change it, so the ledger and code stay in sync.
A3: Rarity | B3: Stat Multiplier | C3: Die.gd Roll Weight (reference only)
A4: Common | B4: 1 | C4: 60
A5: Uncommon | B5: 1.25 | C5: 25
A6: Rare | B6: 1.6 | C6: 10
A7: Epic | B7: 2.1 | C7: 4
A8: Legendary | B8: 3 | C8: 1
A11: Per-Unit Variants
A12: One row per unit x rarity. Damage/HP = Units sheet base stat x the multiplier above. Edit the multipliers, not these rows, to rebalance across the whole roster at once.
A13: Unit Name | B13: Draft Pool | C13: Rarity | D13: Damage | E13: HP | F13: Ability (future)
A14: =Units!$B$2 | B14: =Units!$D$2 | C14: =$A$4 | D14: =ROUND(Units!$F$2*$B$4,1) | E14: =ROUND(Units!$G$2*$B$4,1)
A15: =Units!$B$2 | B15: =Units!$D$2 | C15: =$A$5 | D15: =ROUND(Units!$F$2*$B$5,1) | E15: =ROUND(Units!$G$2*$B$5,1)
A16: =Units!$B$2 | B16: =Units!$D$2 | C16: =$A$6 | D16: =ROUND(Units!$F$2*$B$6,1) | E16: =ROUND(Units!$G$2*$B$6,1)
A17: =Units!$B$2 | B17: =Units!$D$2 | C17: =$A$7 | D17: =ROUND(Units!$F$2*$B$7,1) | E17: =ROUND(Units!$G$2*$B$7,1)
A18: =Units!$B$2 | B18: =Units!$D$2 | C18: =$A$8 | D18: =ROUND(Units!$F$2*$B$8,1) | E18: =ROUND(Units!$G$2*$B$8,1)
A19: =Units!$B$3 | B19: =Units!$D$3 | C19: =$A$4 | D19: =ROUND(Units!$F$3*$B$4,1) | E19: =ROUND(Units!$G$3*$B$4,1)
A20: =Units!$B$3 | B20: =Units!$D$3 | C20: =$A$5 | D20: =ROUND(Units!$F$3*$B$5,1) | E20: =ROUND(Units!$G$3*$B$5,1)
A21: =Units!$B$3 | B21: =Units!$D$3 | C21: =$A$6 | D21: =ROUND(Units!$F$3*$B$6,1) | E21: =ROUND(Units!$G$3*$B$6,1)
A22: =Units!$B$3 | B22: =Units!$D$3 | C22: =$A$7 | D22: =ROUND(Units!$F$3*$B$7,1) | E22: =ROUND(Units!$G$3*$B$7,1)
A23: =Units!$B$3 | B23: =Units!$D$3 | C23: =$A$8 | D23: =ROUND(Units!$F$3*$B$8,1) | E23: =ROUND(Units!$G$3*$B$8,1)
A24: =Units!$B$4 | B24: =Units!$D$4 | C24: =$A$4 | D24: =ROUND(Units!$F$4*$B$4,1) | E24: =ROUND(Units!$G$4*$B$4,1)
A25: =Units!$B$4 | B25: =Units!$D$4 | C25: =$A$5 | D25: =ROUND(Units!$F$4*$B$5,1) | E25: =ROUND(Units!$G$4*$B$5,1)
A26: =Units!$B$4 | B26: =Units!$D$4 | C26: =$A$6 | D26: =ROUND(Units!$F$4*$B$6,1) | E26: =ROUND(Units!$G$4*$B$6,1)
A27: =Units!$B$4 | B27: =Units!$D$4 | C27: =$A$7 | D27: =ROUND(Units!$F$4*$B$7,1) | E27: =ROUND(Units!$G$4*$B$7,1)
A28: =Units!$B$4 | B28: =Units!$D$4 | C28: =$A$8 | D28: =ROUND(Units!$F$4*$B$8,1) | E28: =ROUND(Units!$G$4*$B$8,1)
A29: =Units!$B$5 | B29: =Units!$D$5 | C29: =$A$4 | D29: =ROUND(Units!$F$5*$B$4,1) | E29: =ROUND(Units!$G$5*$B$4,1)
A30: =Units!$B$5 | B30: =Units!$D$5 | C30: =$A$5 | D30: =ROUND(Units!$F$5*$B$5,1) | E30: =ROUND(Units!$G$5*$B$5,1)
A31: =Units!$B$5 | B31: =Units!$D$5 | C31: =$A$6 | D31: =ROUND(Units!$F$5*$B$6,1) | E31: =ROUND(Units!$G$5*$B$6,1)
A32: =Units!$B$5 | B32: =Units!$D$5 | C32: =$A$7 | D32: =ROUND(Units!$F$5*$B$7,1) | E32: =ROUND(Units!$G$5*$B$7,1)
A33: =Units!$B$5 | B33: =Units!$D$5 | C33: =$A$8 | D33: =ROUND(Units!$F$5*$B$8,1) | E33: =ROUND(Units!$G$5*$B$8,1)
A34: =Units!$B$6 | B34: =Units!$D$6 | C34: =$A$4 | D34: =ROUND(Units!$F$6*$B$4,1) | E34: =ROUND(Units!$G$6*$B$4,1)
A35: =Units!$B$6 | B35: =Units!$D$6 | C35: =$A$5 | D35: =ROUND(Units!$F$6*$B$5,1) | E35: =ROUND(Units!$G$6*$B$5,1)
A36: =Units!$B$6 | B36: =Units!$D$6 | C36: =$A$6 | D36: =ROUND(Units!$F$6*$B$6,1) | E36: =ROUND(Units!$G$6*$B$6,1)
A37: =Units!$B$6 | B37: =Units!$D$6 | C37: =$A$7 | D37: =ROUND(Units!$F$6*$B$7,1) | E37: =ROUND(Units!$G$6*$B$7,1)
A38: =Units!$B$6 | B38: =Units!$D$6 | C38: =$A$8 | D38: =ROUND(Units!$F$6*$B$8,1) | E38: =ROUND(Units!$G$6*$B$8,1)
A39: =Units!$B$7 | B39: =Units!$D$7 | C39: =$A$4 | D39: =ROUND(Units!$F$7*$B$4,1) | E39: =ROUND(Units!$G$7*$B$4,1)
A40: =Units!$B$7 | B40: =Units!$D$7 | C40: =$A$5 | D40: =ROUND(Units!$F$7*$B$5,1) | E40: =ROUND(Units!$G$7*$B$5,1)
A41: =Units!$B$7 | B41: =Units!$D$7 | C41: =$A$6 | D41: =ROUND(Units!$F$7*$B$6,1) | E41: =ROUND(Units!$G$7*$B$6,1)
A42: =Units!$B$7 | B42: =Units!$D$7 | C42: =$A$7 | D42: =ROUND(Units!$F$7*$B$7,1) | E42: =ROUND(Units!$G$7*$B$7,1)
...

Sheet Roll Tiers
A1: TYPE roll -> Draft Pool
A2: Mirrors Scripts/main.gd's SUM_TO_RANGE and get_ledger_rows() exactly - this is the same grouping the in-game Roll Ledger button shows. Edit Draft Pool here AND in SUM_TO_RANGE together if you change which sums draft which pool.
A3: Sum Range | B3: 2d6 Sums | C3: Draft Pool | D3: Units Currently in Pool | E3: Notes
A4: 2 | B4: 2 | C4: Boss | D4: =COUNTIF(Units!$D$2:$D$15,$C4)&" units" | E4: Only the single 2-2 roll (1/36 chance) drafts the boss pool.
A5: 3-4 | B5: 3, 4 | C5: Rare | D5: =COUNTIF(Units!$D$2:$D$15,$C5)&" units"
A6: 5-9 | B6: 5, 6, 7, 8, 9 | C6: Common | D6: =COUNTIF(Units!$D$2:$D$15,$C6)&" units" | E6: Bulk of the bell curve - most rolls land here.
A7: 10-12 | B7: 10, 11, 12 | C7: Rare | D7: =COUNTIF(Units!$D$2:$D$15,$C7)&" units" | E7: Same Rare pool as 3-4, reachable from both tails of the curve.

Sheet Village Loadouts
A1: Village Loadouts (5 slots per village)
A2: Per the design doc: the player picks which units fill a village's slots before a raid, rather than every drafted unit auto-joining. Slot count is a column (not hardcoded to 5) since "5" is a current assumption, not locked. Slot cells are dropdowns pulled from the Units sheet's Unit Name column.
A4: Village Name | B4: Village Tier | C4: Win Condition | D4: Slot Count | E4: Slot 1 | F4: Slot 2 | G4: Slot 3 | H4: Slot 4 | I4: Slot 5
A5: Millbrook (example) | B5: Small / Early | C5: Destroy all buildings | D5: 5 | E5: Skull | F5: Gnoll | G5: Gnome | H5: Thief | I5: Turtle
B6: Small / Early | D6: 5
B7: Small / Early | D7: 5
B8: Small / Early | D8: 5
B9: Small / Early | D9: 5
B10: Small / Early | D10: 5
B11: Small / Early | D11: 5

Sheet Dice & Deck Notes
A1: Dice-as-Cards: Open Questions
A2: Scratchpad for the Slay-the-Spire-style dice bag/hand idea, kept separate from the roster above since none of it is mechanically wired yet - none of this changes Scripts/Die.gd or main.gd on its own.
A4: Question | B4: Current Idea | C4: Depends On | D4: Status
A5: Bag size (total dice owned) | B5: TBD - StS decks start ~10 cards and grow | C5: Run-length pacing, shop economy | D5: Open
A6: Hand size per roll | B6: TBD - currently the game just rolls a fixed 2 dice for TYPE, then a fixed 3 for QUANTITY (no hand yet) | C6: How many meaningful choices per roll feels good | D6: Open
A7: Draw timing | B7: Per roll? Per village? Per run? | C7: Whether swapping dice is a mid-raid tactic or a prep-phase one | D7: Open
A8: Dice you choose to play vs. auto-rolled | B8: Player picks which dice from hand to roll, to sway TYPE sum toward a Draft Pool or QUANTITY rarity | C8: Needs a real hand UI - see Scripts/DiceCountSelector.gd, parked for rework | D8: Open
A9: One-time-use vs. persistent dice | B9: Some dice consumed after one roll (like a StS card exhausting), most stay in the bag | C9: Shop/reward design for how you acquire them | D9: Open
A10: Modifier dice - raise/lower roll | B10: A die that adds/subtracts from the TYPE sum before it's looked up in Roll Tiers | C10: Needs a resolution step in main.gd between dice locking and _pool_for_range() | D10: Open
A11: Modifier dice - stat trade | B11: "Glass cannon" (+damage/-HP) or "tanky" (-damage/+HP) roll modifiers applied to the drafted unit's Rarity Variants row | C11: Needs the Rarity Variants sheet's Damage/HP columns to support a runtime trade, not just the static multiplier | D11: Open
A12: 5 unit slots per village | B12: Player pre-picks which units can be drafted for a given village (see Village Loadouts tab) rather than the full roster always being live | C12: Whether Draft Pool filtering happens before or after the dice roll | D12: Open
